<?xml version="1.0"?>
<robot xmlns:xacro="http://ros.org/wiki/xacro">
  <xacro:macro name="create_arm" params="connected_to:='' xyz:='0 0 0' rpy:='0 0 0'">
    <xacro:unless value="${connected_to==''}">
      <joint name="arm_base_joint" type="fixed">
        <parent link="${connected_to}"/>
        <child link="arm_base_link"/>
        <origin rpy="${rpy}" xyz="${xyz}"/>
      </joint>
    </xacro:unless>

    <xacro:macro name="inertial_cuboid_with_pose" params="mass x_length y_length z_length *origin">
      <inertial>
        <xacro:insert_block name="origin"/>
        <mass value="${mass}" />
        <inertia ixx="${(1/12) * mass * (y_length*y_length + z_length*z_length)}" ixy="0.0" ixz="0.0"
                 iyy="${(1/12) * mass * (x_length*x_length + z_length*z_length)}" iyz="0.0"
                 izz="${(1/12) * mass * (x_length*x_length + y_length*y_length)}" />
      </inertial>
    </xacro:macro>

    <xacro:macro name="inertial_cylinder_with_pose" params="mass radius length *origin">
      <inertial>
        <xacro:insert_block name="origin"/>
        <mass value="${mass}" />
        <xacro:insert_block name="origin" />
        <inertia ixx="${0.0833333 * mass * (3 * radius * radius + length * length)}" ixy="0.0" ixz="0.0"
          iyy="${0.0833333 * mass * (3 * radius * radius + length * length)}" iyz="0.0"
          izz="${0.5 * mass * radius * radius}" />
      </inertial>
    </xacro:macro>

    <link
      name="arm_base_link">
      <inertial_cuboid_with_pose
        mass="0.2"
        x_length="0.2"
        y_length="0.2"
        z_length="0.008">
        <origin xyz="0 0 0"  rpy="0 0 0"/>
      </inertial_cuboid_with_pose>
      <visual>
        <origin xyz="0 0 -0.004"  rpy="0 0 0"/>
        <geometry>
          <mesh
            filename="package://protobot_arm_description/meshes/base_link.STL" scale="0.001 0.001 0.001"/>
        </geometry>
        <material
          name="">
          <color
            rgba="0.75294 0.75294 0.75294 1" />
        </material>
      </visual>
      <collision>
        <origin
          xyz="0 0 0"
          rpy="0 0 0" />
        <geometry>
          <box size="0.2 0.2 0.008"/>
        </geometry>
      </collision>
    </link>
    <link
      name="rot_link">
      <inertial_cylinder_with_pose
        mass="1.5"
        radius="0.1"
        length="0.1">
        <origin xyz="0 0 0.05"  rpy="0 0 0"/>
      </inertial_cylinder_with_pose>
      <visual>
        <origin
          xyz="0 0 0"
          rpy="0 0 0" />
        <geometry>
          <mesh
            filename="package://protobot_arm_description/meshes/rot_link.STL" scale="0.001 0.001 0.001"/>
        </geometry>
        <material
          name="">
          <color
            rgba="0.75294 0.75294 0.75294 1" />
        </material>
      </visual>
      <collision>
        <origin
          xyz="0 0 0"
          rpy="0 0 0" />
        <geometry>
          <mesh
            filename="package://protobot_arm_description/meshes/rot_collision.STL"/>
        </geometry>
      </collision>
    </link>
    <joint
      name="rot_joint"
      type="continuous">
      <origin
        xyz="0 0 0.004"
        rpy="0 0 0" />
      <parent
        link="arm_base_link" />
      <child
        link="rot_link" />
      <axis
        xyz="0 0 1" />
      <limit
        effort="100"
        velocity="1.0"/>
    </joint>
    <link
      name="umotor_link">
      <inertial_cylinder_with_pose
        mass="1.0"
        radius="0.03"
        length="0.1">
        <origin xyz="0 0.05 0"  rpy="-1.5707 0 0"/>
      </inertial_cylinder_with_pose>
      <visual>
        <origin xyz="0 0 0" rpy="-1.5707 0 0" />
        <geometry>
          <mesh
            filename="package://protobot_arm_description/meshes/motor_link.STL" scale="0.001 0.001 0.001"/>
        </geometry>
        <material
          name="">
          <color
            rgba="0.75294 0.75294 0.75294 1" />
        </material>
      </visual>
      <collision>
        <origin xyz="0 0.05 0"  rpy="-1.5707 0 0" />
        <geometry>
          <cylinder radius="0.03" length="0.1"/>
        </geometry>
      </collision>
    </link>
    <joint
      name="umotor_joint"
      type="fixed">
      <origin
        xyz="0 -0.056 0.161"
        rpy="0 0 0" />
      <parent
        link="rot_link" />
      <child
        link="umotor_link" />
    </joint>
    <link
      name="uarm_link">
      <inertial_cuboid_with_pose
        mass="1.0"
        x_length="0.1"
        y_length="0.05"
        z_length="0.5">
        <origin xyz="0 -0.02 0.2"  rpy="0 0 3.1415926"/>
      </inertial_cuboid_with_pose>
      <visual>
        <origin
          xyz="0 0 0"
          rpy="0 0 3.1415926" />
        <geometry>
          <mesh
            filename="package://protobot_arm_description/meshes/arm_link.STL" scale="0.001 0.001 0.001"/>
        </geometry>
        <material
          name="">
          <color
            rgba="0.75294 0.75294 0.75294 1" />
        </material>
      </visual>
      <collision>
        <origin
          xyz="0 0.004 0"
          rpy="0 0 3.1415926" />
        <geometry>
          <mesh
            filename="package://protobot_arm_description/meshes/arm_collision.STL" />
        </geometry>
      </collision>
    </link>
    <joint
      name="uarm_joint"
      type="revolute">
      <origin
        xyz="0 0.1 0"
        rpy="0 0 0" />
      <parent
        link="umotor_link" />
      <child
        link="uarm_link" />
      <axis
        xyz="0 -1 0" />
      <limit
        lower="-1.5707"
        upper="1.5707"
        effort="100"
        velocity="0.500"/>
    </joint>
    <link
      name="lmotor_link">
      <inertial_cylinder_with_pose
        mass="1.0"
        radius="0.03"
        length="0.1">
        <origin xyz="0 0.05 0"  rpy="-1.5707 0 0"/>
      </inertial_cylinder_with_pose>
      <visual>
        <origin xyz="0 0 0" rpy="-1.5707 1.5707 0" />
        <geometry>
          <mesh
            filename="package://protobot_arm_description/meshes/motor_link.STL" scale="0.001 0.001 0.001"/>
        </geometry>
        <material
          name="">
          <color
            rgba="0.75294 0.75294 0.75294 1" />
        </material>
      </visual>
      <collision>
        <origin xyz="0 0.05 0"  rpy="-1.5707 0 0" />
        <geometry>
          <cylinder radius="0.03" length="0.1"/>
        </geometry>
      </collision>
    </link>
    <joint
      name="lmotor_joint"
      type="fixed">
      <origin
        xyz="0 -0.048 0.4"
        rpy="0 0 0" />
      <parent
        link="uarm_link" />
      <child
        link="lmotor_link" />
    </joint>
    <link
      name="larm_link">
      <inertial_cuboid_with_pose
        mass="1.0"
        x_length="0.1"
        y_length="0.05"
        z_length="0.5">
        <origin xyz="0 -0.02 0.2"  rpy="0 0 3.1415926"/>
      </inertial_cuboid_with_pose>
      <visual>
        <origin
          xyz="0 0 0"
          rpy="0 0 3.1415926" />
        <geometry>
          <mesh
            filename="package://protobot_arm_description/meshes/arm_link.STL" scale="0.001 0.001 0.001"/>
        </geometry>
        <material
          name="">
          <color
            rgba="0.75294 0.75294 0.75294 1" />
        </material>
      </visual>
      <collision>
        <origin
          xyz="0 0.004 0"
          rpy="0 0 3.1415926" />
        <geometry>
          <mesh
            filename="package://protobot_arm_description/meshes/arm_collision.STL" />
        </geometry>
      </collision>
    </link>
    <joint
      name="larm_joint"
      type="continuous">
      <origin
        xyz="0 0.11 0"
        rpy="0 0 0" />
      <parent
        link="lmotor_link" />
      <child
        link="larm_link" />
      <axis
        xyz="0 -1 0" />
      <limit
        effort="100"
        velocity="1.000"/>
    </joint>
    <link name="fake_motor_link">
      <inertial_cylinder_with_pose
        mass="0.25"
        radius="0.03"
        length="0.05">
        <origin xyz="0 0.025 0"  rpy="-1.5707 0 0"/>
      </inertial_cylinder_with_pose>
      <visual>
        <origin xyz="0 0.025 0"  rpy="-1.5707 0 0" />
        <geometry>
          <cylinder radius="0.03" length="0.05"/>
        </geometry>
        <material
          name="">
          <color
            rgba="0.75294 0.75294 0.75294 1" />
        </material>
      </visual>
      <collision>
        <origin xyz="0 0.025 0"  rpy="-1.5707 0 0" />
        <geometry>
          <cylinder radius="0.03" length="0.05"/>
        </geometry>
      </collision>
    </link>
    <joint 
       name="passive1_joint"
       type="continuous">
      <origin
        xyz="0 -0.015 0.4"
        rpy="0 0 0" />
      <parent
        link="larm_link" />
      <child
        link="fake_motor_link" />
      <axis xyz="0 -1 0" />
      <mimic joint="uarm_joint" multiplier="-1.000"/>
    </joint>

    <link
      name="end_link">
      <inertial_cylinder_with_pose
        mass="0.25"
        radius="0.05"
        length="0.04">
        <origin xyz="0 0.02 0"  rpy="-1.5707 0 0"/>
      </inertial_cylinder_with_pose>
      <visual>
        <origin
          xyz="0 0 0"
          rpy="0 0 3.1415926" />
        <geometry>
          <mesh
            filename="package://protobot_arm_description/meshes/end_link.STL" scale="0.001 0.001 0.001"/>
        </geometry>
        <material
          name="">
          <color
            rgba="0.75294 0.75294 0.75294 1" />
        </material>
      </visual>
      <collision>
        <origin xyz="0 0.02 0"  rpy="-1.5707 0 0" />
        <geometry>
          <cylinder radius="0.05" length="0.04"/>
        </geometry>
      </collision>
    </link>
    <joint
      name="passive2_joint"
      type="continuous">
      <origin
        xyz="0 0.045 0"
        rpy="0 0 0" />
      <parent
        link="fake_motor_link" />
      <child
        link="end_link" />
      <axis
        xyz="0 -1 0" />
      <mimic joint="larm_joint" multiplier="-1.000"/>
    </joint>
    <link
      name="flange_motor_link">
      <inertial_cylinder_with_pose
        mass="1.0"
        radius="0.03"
        length="0.1">
        <origin xyz="0 0 0.05"  rpy="0 0 0"/>
      </inertial_cylinder_with_pose>
      <visual>
        <origin xyz="0 0 0.1" rpy="0 3.1415926 0" />
        <geometry>
          <mesh
            filename="package://protobot_arm_description/meshes/motor_link.STL" scale="0.001 0.001 0.001"/>
        </geometry>
        <material
          name="">
          <color
            rgba="0.75294 0.75294 0.75294 1" />
        </material>
      </visual>
      <collision>
        <origin xyz="0 0 0.05"  rpy="0 0 0" />
        <geometry>
          <cylinder radius="0.03" length="0.1"/>
        </geometry>
      </collision>
    </link>
    <joint
      name="flange_joint"
      type="continuous">
      <origin
        xyz="0 0.02 -0.15"
        rpy="0 0 0" />
      <parent
        link="end_link" />
      <child
        link="flange_motor_link" />
      <axis
        xyz="0 0 1" />
      <limit
        effort="100"
        velocity="1.000"/>
    </joint>
  </xacro:macro>
</robot>
